Workbook

Sheet Map
B2: Master Warranty Reference Map
B4: Manufacturers | D4: Manufacturer | E4: OTA Model Name | F4: Mfg Product Code | G4: Drive Folder Link | J4: Error Code Display Mechanism | M4: Monday Morning Mike Notes
B5: Annmacare | D5: Annmacare | E5: Reflex | F5: AM-5110 | G5: https://drive.google.com/drive/folders/1Guxr2dEjIGU9C6cGWVLo0OqXo_A2cHqc?usp=drive_link | J5: User Prompted (Entry Method) | M5: -Incredible progress dude
B6: Behealthy | D6: Annmacare | E6: Solis | F6: AM-1700B | G6: https://drive.google.com/drive/folders/131_3CMMissMjWH1ALFuXTD0tN6R66nKO?usp=drive_link | J6: Tablet/Remote Display: Numeric Code | M6: -I will add older service manuals that are missing. I have quite a few, likely from when tech site was rebuilt
B7: Easepal | D7: Behealthy | E7: Sapphire | F7: YA113W | G7: https://drive.google.com/drive/folders/1aLp-OuMzR1StTckVfg9DOco1nx8k9OV8?usp=drive_link | J7: Tablet/Remote Display: Timer Display | M7: -Adjacent projects (in terms of priority) to consider IMO:
B8: Fujian Rovos | D8: Easepal | E8: 4000 | F8: Unknown | G8: https://drive.google.com/drive/folders/1nm230_KtGmC42RaFbPe2OSkSn5I_ETz1?usp=drive_link | N8: Parts & Related chair. Need to brainstorm how this works but essentially the goal would be to map related chairs (e.g. x-rest and master, nexus/maestro/hilux/3-5 others i need to sit down and fig out). AI Heavy
B9: GoJoy | D9: Easepal | E9: 4000CS | F9: Unknown | G9: https://drive.google.com/drive/folders/1z11IbEq3O3W76NGgaSDLFIxc9HfSvAjh?usp=drive_link | M9: -Try my claude account. I have claude max plan so i have the newest model (fable). you'll need to set up a project (I can walk you through) but i think it make a lot of gains for you on the planning side (and really any advanced logic)
B10: Inada | D10: Easepal | E10: 4000LE | F10: EC-5653A
B11: iRest | D11: Easepal | E11: 4000LS | F11: EC-623B | G11: https://drive.google.com/drive/folders/1teV4oL4c5RcqaLqL3YgkTxT8u_lgvAlk?usp=drive_link
B12: Kangtai | D12: Easepal | E12: 4000T | F12: EC-380D | G12: https://drive.google.com/drive/folders/1HVO7x1E7kqDy8_9wHs4qhubRiz9mMdMS?usp=drive_link
B13: Kosei | D13: Easepal | E13: 4000XT | F13: EC-3205H | G13: https://drive.google.com/drive/folders/1xVyfj2tmIlOU9QLLx3o164wTMxPy4R2c?usp=drive_link
B14: Rotai | D14: Easepal | E14: 4500LS | F14: Unknown
B15: Rovos | D15: Easepal | E15: 7200H Pinnacle | F15: YH-8382L | G15: https://drive.google.com/drive/folders/1ggmyJRvMFA5K1qDhXyjYqrwDjIvs010m?usp=drive_link
B16: Yihocon | D16: Easepal | E16: Ace II | F16: Unknown | G16: https://drive.google.com/drive/folders/1ihioy4QmXBIxRboSurrTr15sz0xndfUS?usp=drive_link
B17: Zhouqi | D17: Easepal | E17: Admiral II | F17: EC-7506Q | G17: https://drive.google.com/drive/folders/18eY3HxpLrtyhpN9jfrPwe2PLVdV0rYsV?usp=drive_link
D18: Easepal | E18: Alma II | F18: Unknown | G18: https://drive.google.com/drive/folders/1HQGswoMFV5l1Jt02XUdH1cfuUvf88bSj?usp=drive_link
D19: Easepal | E19: Alpina | F19: Unknown | G19: https://drive.google.com/drive/folders/1Lb7RbcSTrmR3-0MVjFwkHiqxzd_H0qt4?usp=drive_link
D20: Easepal | E20: Alpine | F20: EC-621C | G20: https://drive.google.com/drive/folders/1eSAFNh1WLgy6XVUUDPrATrY7a9qDAS_W?usp=drive_link
D21: Easepal | E21: Arcadia 3D LE | F21: YH-8382L
D22: Easepal | E22: Aspire | F22: EC-3622A | G22: https://drive.google.com/drive/folders/1u2aYBj_Za7SC1UeOV5TJGQCNUSYblfo2?usp=drive_link
D23: Easepal | E23: Aurora | F23: Unknown | G23: https://drive.google.com/drive/folders/1zIFYX9OQZUkU4ihcXXoiiyxhKRTtD9AU?usp=drive_link
D24: Easepal | E24: Bello | F24: Unknown | G24: https://drive.google.com/drive/folders/1sEpMbmI8fUMsVS07IjG1u1GZE8W4nTdk?usp=drive_link
D25: Easepal | E25: Champ | F25: OGI-3210G | G25: https://drive.google.com/drive/folders/1xFw_gmdtx4ZINXGhFh8IQ27OoC0wxT3d?usp=drive_link
D26: Easepal | E26: Champ II | F26: YH-8380L | G26: https://drive.google.com/drive/folders/1SOpLuavnl0_oZmcpbAx5JImfGb7Z5Vfj?usp=drive_link
D27: Easepal | E27: Commander | F27: Unknown | G27: https://drive.google.com/drive/folders/13ncQTz2ED3q21LbWvUabJuicmoZoSooN?usp=drive_link
D28: Easepal | E28: Cyber | F28: EC-381E | G28: https://drive.google.com/drive/folders/1RJvx8ElWyLJ59QZL3Q3SiIVagtOz49Wj?usp=drive_link
D29: Easepal | E29: Emperor | F29: EC-8606B | G29: https://drive.google.com/drive/folders/1d0zV5bG3uYErO7_k-vx8HAQxBf62-z2_?usp=drive_link
D30: Easepal | E30: Emperor II | F30: EC-8608S
D31: Easepal | E31: Envy | F31: EC-7516E | G31: https://drive.google.com/drive/folders/1npf8fxw-vxATg-KUbDF1uKA--hyOr1W2?usp=drive_link
D32: Easepal | E32: Escape Duo | F32: EC-8638A | G32: https://drive.google.com/drive/folders/1GoDfLGTRow5jsCsU5_HeQtjfMELyKJ_3?usp=drive_link
D33: Easepal | E33: Hilux | F33: EC-8606B | G33: https://drive.google.com/drive/folders/11B0FxI_FWNeQfZ2piR_JVog6WmFiQvaD?usp=drive_link
D34: Easepal | E34: Hiro LT | F34: EI-8602A | G34: https://drive.google.com/drive/folders/1aF-d-pNu2efQC06blxtVSNd3xcJ3EvMC?usp=drive_link
D35: Easepal | E35: Honor | F35: Unknown | G35: https://drive.google.com/drive/folders/1la3NEwHRbxDaSV7jhEQ3PgtPtPD4a_xi?usp=drive_link
D36: Easepal | E36: Hypnos | F36: EC-6701B
D37: Easepal | E37: Juno II | F37: EC-3209M | G37: https://drive.google.com/drive/folders/1lKzm3-0XyS8oK5OkRzpSpNeQhYrTrAmV?usp=drive_link
D38: Easepal | E38: Luca V | F38: EI-8602A | G38: https://drive.google.com/drive/folders/1UuiMu753WlFBJGYQIrNWf7L6lMry-Htp?usp=drive_link
D39: Easepal | E39: Maestro | F39: EC-806A | G39: https://drive.google.com/drive/folders/1ci6Z_jMNS3Vz-vtNef_g49IqyO4D8BVT?usp=drive_link
D40: Easepal | E40: Maestro LE | F40: EC-806C | G40: https://drive.google.com/drive/folders/1HOWMMoy8m_NOgGGve9S7r2b40MA0-qd0?usp=drive_link
D41: Easepal | E41: Maestro LE 2.0 | F41: EC-806R | G41: https://drive.google.com/drive/folders/1bazhAKh9WFATDEJ-JVsovxXQKf2OTwgf?usp=drive_link
D42: Easepal | E42: Manhattan Duo | F42: EC-8507B | G42: https://drive.google.com/drive/folders/1ep4m1vWDrKtlr_8l5pbK-1v3rbo1NOXP?usp=drive_link
...

Sheet Summary by Mfg & Model
A1: Mfg | B1: Mfg Product Code | C1: OTA Model Name | D1: Total Error Codes | E1: Entry Method? | F1: Entry Procedure | G1: Error Code Access Type
A2: Annmacare | B2: AM-5110 | C2: Reflex | D2: 6 | E2: No | G2: =IF(ISNUMBER(SEARCH("!HAS TIMER DISPLAYS!", F2)), "Tablet/Remote Display: Timer Display", IF(E2="No", "Tablet/Remote Display: Numeric Code", IF(E2="Yes", "User Prompted (Entry Method)", ""))) -> Tablet/Remote Display: Numeric Code
A3: Annmacare | B3: AM-1700B | C3: Solis | D3: 0 | E3: N/A | F3: (No Error Codes) | G3: =IF(ISNUMBER(SEARCH("!HAS TIMER DISPLAYS!", F3)), "Tablet/Remote Display: Timer Display", IF(E3="No", "Tablet/Remote Display: Numeric Code", IF(E3="Yes", "User Prompted (Entry Method)", "")))
A4: Behealthy | B4: YA113W | C4: Sapphire | D4: 81 | E4: No | G4: =IF(ISNUMBER(SEARCH("!HAS TIMER DISPLAYS!", F4)), "Tablet/Remote Display: Timer Display", IF(E4="No", "Tablet/Remote Display: Numeric Code", IF(E4="Yes", "User Prompted (Entry Method)", ""))) -> Tablet/Remote Display: Numeric Code
A5: Easepal | B5: Unknown | C5: 4000 | D5: =COUNTIF('Error Code Log'!B:B, "4000") -> 13 | E5: No | G5: =IF(ISNUMBER(SEARCH("!HAS TIMER DISPLAYS!", F5)), "Tablet/Remote Display: Timer Display", IF(E5="No", "Tablet/Remote Display: Numeric Code", IF(E5="Yes", "User Prompted (Entry Method)", ""))) -> Tablet/Remote Display: Numeric Code
A6: Easepal | B6: Unknown | C6: 4000CS | D6: =COUNTIF('Error Code Log'!B:B, "4000CS") -> 17 | E6: Yes | F6: !HAS TIMER DISPLAYS! KNEAD + TAP + POWER (buttons on the controller), press and hold the three buttons in two seconds to turn on the automatic analysis system mode. | G6: =IF(ISNUMBER(SEARCH("!HAS TIMER DISPLAYS!", F6)), "Tablet/Remote Display: Timer Display", IF(E6="No", "Tablet/Remote Display: Numeric Code", IF(E6="Yes", "User Prompted (Entry Method)", ""))) -> Tablet/Remote Display: Timer Display
A7: Easepal | B7: EC-5653A | C7: 4000LE | D7: =COUNTIF('Error Code Log'!$B:$B, C7) -> 16 | E7: Yes | F7: Press and hold the settings icon/button for **4 seconds** to enter the password screen. Enter the password **0592** to enter the engineering mode interface. | G7: =IF(ISNUMBER(SEARCH("!HAS TIMER DISPLAYS!", F7)), "Tablet/Remote Display: Timer Display", IF(E7="No", "Tablet/Remote Display: Numeric Code", IF(E7="Yes", "User Prompted (Entry Method)", ""))) -> User Prompted (Entry Method)
A8: Easepal | B8: EC-623B | C8: 4000LS | D8: 0 | E8: N/A | F8: (No Error Codes) | G8: =IF(ISNUMBER(SEARCH("!HAS TIMER DISPLAYS!", F8)), "Tablet/Remote Display: Timer Display", IF(E8="No", "Tablet/Remote Display: Numeric Code", IF(E8="Yes", "User Prompted (Entry Method)", "")))
A9: Easepal | B9: EC-380D | C9: 4000T | D9: 17 | E9: Yes | F9: !HAS TIMER DISPLAYS! KNEAD + TAP + POWER (buttons on the controller), press and hold the three buttons in two seconds to turn on the automatic analysis system mode. | G9: =IF(ISNUMBER(SEARCH("!HAS TIMER DISPLAYS!", F9)), "Tablet/Remote Display: Timer Display", IF(E9="No", "Tablet/Remote Display: Numeric Code", IF(E9="Yes", "User Prompted (Entry Method)", ""))) -> Tablet/Remote Display: Timer Display
A10: Easepal | B10: EC-3205H | C10: 4000XT | D10: =COUNTIF('Error Code Log'!B:B, C10) -> 9 | E10: No | G10: =IF(ISNUMBER(SEARCH("!HAS TIMER DISPLAYS!", F10)), "Tablet/Remote Display: Timer Display", IF(E10="No", "Tablet/Remote Display: Numeric Code", IF(E10="Yes", "User Prompted (Entry Method)", ""))) -> Tablet/Remote Display: Numeric Code
A11: Easepal | B11: Unknown | C11: 4500LS | D11: 0 | E11: N/A | F11: No information at this time | G11: =IF(ISNUMBER(SEARCH("!HAS TIMER DISPLAYS!", F11)), "Tablet/Remote Display: Timer Display", IF(E11="No", "Tablet/Remote Display: Numeric Code", IF(E11="Yes", "User Prompted (Entry Method)", "")))
A12: Easepal | B12: YH-8382L | C12: 7200H Pinnacle | D12: =COUNTIF('Error Code Log'!B:B, C12) -> 24 | E12: Yes | F12: Press and hold the KNEAD + TAP + POWER buttons on the controller for two seconds to turn on or turn off the automatic analysis system/auto-checking model. | G12: =IF(ISNUMBER(SEARCH("!HAS TIMER DISPLAYS!", F12)), "Tablet/Remote Display: Timer Display", IF(E12="No", "Tablet/Remote Display: Numeric Code", IF(E12="Yes", "User Prompted (Entry Method)", ""))) -> User Prompted (Entry Method)
A13: Easepal | B13: Unknown | C13: Ace II | D13: =COUNTIF('Error Code Log'!$B:$B, C13) -> 0 | E13: N/A | F13: (No Error Codes) | G13: =IF(ISNUMBER(SEARCH("!HAS TIMER DISPLAYS!", F13)), "Tablet/Remote Display: Timer Display", IF(E13="No", "Tablet/Remote Display: Numeric Code", IF(E13="Yes", "User Prompted (Entry Method)", "")))
A14: Easepal | B14: EC-7506Q | C14: Admiral II | D14: =COUNTIF('Error Code Log'!B:B, C14) -> 27 | E14: Yes | F14: Enter the settings page, press the blank at the bottom of the settings page for a long time, pop up the page and enter the password 0592, enter the mode selection page, select the AUTO key, and switch to the self-checking mode. | G14: =IF(ISNUMBER(SEARCH("!HAS TIMER DISPLAYS!", F14)), "Tablet/Remote Display: Timer Display", IF(E14="No", "Tablet/Remote Display: Numeric Code", IF(E14="Yes", "User Prompted (Entry Method)", ""))) -> User Prompted (Entry Method)
A15: Easepal | B15: Unknown | C15: Alma II | D15: =COUNTIF('Error Code Log'!$B:$B, C15) -> 0 | E15: N/A | F15: No information at this time | G15: =IF(ISNUMBER(SEARCH("!HAS TIMER DISPLAYS!", F15)), "Tablet/Remote Display: Timer Display", IF(E15="No", "Tablet/Remote Display: Numeric Code", IF(E15="Yes", "User Prompted (Entry Method)", "")))
A16: Easepal | B16: Unknown | C16: Alpina | D16: =COUNTIF('Error Code Log'!$B:$B, C16) -> 0 | E16: N/A | F16: (No Error Codes) | G16: =IF(ISNUMBER(SEARCH("!HAS TIMER DISPLAYS!", F16)), "Tablet/Remote Display: Timer Display", IF(E16="No", "Tablet/Remote Display: Numeric Code", IF(E16="Yes", "User Prompted (Entry Method)", "")))
A17: Easepal | B17: EC-621C | C17: Alpine | D17: =COUNTIF('Error Code Log'!$B:$B, C17) -> 0 | E17: N/A | F17: (No Error Codes) | G17: =IF(ISNUMBER(SEARCH("!HAS TIMER DISPLAYS!", F17)), "Tablet/Remote Display: Timer Display", IF(E17="No", "Tablet/Remote Display: Numeric Code", IF(E17="Yes", "User Prompted (Entry Method)", "")))
A18: Easepal | B18: YH-8382L | C18: Arcadia 3D LE | D18: 8 | E18: No | G18: =IF(ISNUMBER(SEARCH("!HAS TIMER DISPLAYS!", F18)), "Tablet/Remote Display: Timer Display", IF(E18="No", "Tablet/Remote Display: Numeric Code", IF(E18="Yes", "User Prompted (Entry Method)", ""))) -> Tablet/Remote Display: Numeric Code
A19: Easepal | B19: EC-3622A | C19: Aspire | D19: 17 | E19: Yes | F19: On/Off: Press and hold the Settings lettering in Settings for 4 seconds to enter the password field, enter 0592, and enter the engineering mode interface. | G19: =IF(ISNUMBER(SEARCH("!HAS TIMER DISPLAYS!", F19)), "Tablet/Remote Display: Timer Display", IF(E19="No", "Tablet/Remote Display: Numeric Code", IF(E19="Yes", "User Prompted (Entry Method)", ""))) -> User Prompted (Entry Method)
A20: Easepal | B20: Unknown | C20: Aurora | D20: =COUNTIF('Error Code Log'!$B:$B, C20) -> 0 | E20: N/A | F20: No information at this time | G20: =IF(ISNUMBER(SEARCH("!HAS TIMER DISPLAYS!", F20)), "Tablet/Remote Display: Timer Display", IF(E20="No", "Tablet/Remote Display: Numeric Code", IF(E20="Yes", "User Prompted (Entry Method)", "")))
A21: Easepal | B21: Unknown | C21: Bello | D21: =COUNTIF('Error Code Log'!$B:$B, C21) -> 0 | E21: N/A | F21: (No Error Codes) | G21: =IF(ISNUMBER(SEARCH("!HAS TIMER DISPLAYS!", F21)), "Tablet/Remote Display: Timer Display", IF(E21="No", "Tablet/Remote Display: Numeric Code", IF(E21="Yes", "User Prompted (Entry Method)", "")))
A22: Easepal | B22: OGI-3210G | C22: Champ | D22: =COUNTIF('Error Code Log'!$B:$B, C22) -> 0 | E22: N/A | F22: (No Error Codes) | G22: =IF(ISNUMBER(SEARCH("!HAS TIMER DISPLAYS!", F22)), "Tablet/Remote Display: Timer Display", IF(E22="No", "Tablet/Remote Display: Numeric Code", IF(E22="Yes", "User Prompted (Entry Method)", "")))
A23: Easepal | B23: YH-8380L | C23: Champ II | D23: =COUNTIF('Error Code Log'!$B:$B, C23) -> 0 | E23: N/A | F23: (No Error Codes) | G23: =IF(ISNUMBER(SEARCH("!HAS TIMER DISPLAYS!", F23)), "Tablet/Remote Display: Timer Display", IF(E23="No", "Tablet/Remote Display: Numeric Code", IF(E23="Yes", "User Prompted (Entry Method)", "")))
A24: Easepal | B24: Unknown | C24: Commander | D24: =COUNTIF('Error Code Log'!$B:$B, C24) -> 0 | E24: N/A | F24: (No Error Codes) | G24: =IF(ISNUMBER(SEARCH("!HAS TIMER DISPLAYS!", F24)), "Tablet/Remote Display: Timer Display", IF(E24="No", "Tablet/Remote Display: Numeric Code", IF(E24="Yes", "User Prompted (Entry Method)", "")))
A25: Easepal | B25: EC-381E | C25: Cyber | D25: 20 | E25: Yes | F25: !HAS TIMER DISPLAYS! KNEAD + TAP + POWER (buttons on the controller), press and hold the three buttons in two seconds to turn on the automatic analysis system mode. | G25: =IF(ISNUMBER(SEARCH("!HAS TIMER DISPLAYS!", F25)), "Tablet/Remote Display: Timer Display", IF(E25="No", "Tablet/Remote Display: Numeric Code", IF(E25="Yes", "User Prompted (Entry Method)", ""))) -> Tablet/Remote Display: Timer Display
A26: Easepal | B26: EC-8606B | C26: Emperor | D26: =COUNTIFS('Error Code Log'!B:B, C26) -> 22 | E26: No | G26: =IF(ISNUMBER(SEARCH("!HAS TIMER DISPLAYS!", F26)), "Tablet/Remote Display: Timer Display", IF(E26="No", "Tablet/Remote Display: Numeric Code", IF(E26="Yes", "User Prompted (Entry Method)", ""))) -> Tablet/Remote Display: Numeric Code
A27: Easepal | B27: EC-8608S | C27: Emperor II | D27: 0 | E27: N/A | F27: No information at this time | G27: =IF(ISNUMBER(SEARCH("!HAS TIMER DISPLAYS!", F27)), "Tablet/Remote Display: Timer Display", IF(E27="No", "Tablet/Remote Display: Numeric Code", IF(E27="Yes", "User Prompted (Entry Method)", "")))
A28: Easepal | B28: EC-7516E | C28: Envy | D28: =COUNTIFS('Error Code Log'!B:B, C28) -> 30 | E28: No | G28: =IF(ISNUMBER(SEARCH("!HAS TIMER DISPLAYS!", F28)), "Tablet/Remote Display: Timer Display", IF(E28="No", "Tablet/Remote Display: Numeric Code", IF(E28="Yes", "User Prompted (Entry Method)", ""))) -> Tablet/Remote Display: Numeric Code
A29: Easepal | B29: EC-8638A | C29: Escape Duo | D29: =COUNTIFS('Error Code Log'!B:B, C29) -> 45 | E29: Yes | F29: Select Auto Check in Menu | G29: =IF(ISNUMBER(SEARCH("!HAS TIMER DISPLAYS!", F29)), "Tablet/Remote Display: Timer Display", IF(E29="No", "Tablet/Remote Display: Numeric Code", IF(E29="Yes", "User Prompted (Entry Method)", ""))) -> User Prompted (Entry Method)
A30: Easepal | B30: EC-8606B | C30: Hilux | D30: =COUNTIFS('Error Code Log'!B:B, C30) -> 22 | E30: No | G30: =IF(ISNUMBER(SEARCH("!HAS TIMER DISPLAYS!", F30)), "Tablet/Remote Display: Timer Display", IF(E30="No", "Tablet/Remote Display: Numeric Code", IF(E30="Yes", "User Prompted (Entry Method)", ""))) -> Tablet/Remote Display: Numeric Code
A31: Easepal | B31: EI-8602A | C31: Hiro LT | D31: =COUNTIFS('Error Code Log'!B:B, C31) -> 13 | E31: No | G31: =IF(ISNUMBER(SEARCH("!HAS TIMER DISPLAYS!", F31)), "Tablet/Remote Display: Timer Display", IF(E31="No", "Tablet/Remote Display: Numeric Code", IF(E31="Yes", "User Prompted (Entry Method)", ""))) -> Tablet/Remote Display: Numeric Code
A32: Easepal | B32: Unknown | C32: Honor | D32: =COUNTIFS('Error Code Log'!B:B, C32) -> 12 | E32: No | G32: =IF(ISNUMBER(SEARCH("!HAS TIMER DISPLAYS!", F32)), "Tablet/Remote Display: Timer Display", IF(E32="No", "Tablet/Remote Display: Numeric Code", IF(E32="Yes", "User Prompted (Entry Method)", ""))) -> Tablet/Remote Display: Numeric Code
A33: Easepal | B33: EC-6701B | C33: Hypnos | D33: 22 | E33: No | G33: =IF(ISNUMBER(SEARCH("!HAS TIMER DISPLAYS!", F33)), "Tablet/Remote Display: Timer Display", IF(E33="No", "Tablet/Remote Display: Numeric Code", IF(E33="Yes", "User Prompted (Entry Method)", ""))) -> Tablet/Remote Display: Numeric Code
A34: Easepal | B34: EC-3209M | C34: Juno II | D34: =COUNTIFS('Error Code Log'!B:B, C34) -> 17 | E34: No | F34: !HAS TIMER DISPLAYS! | G34: =IF(ISNUMBER(SEARCH("!HAS TIMER DISPLAYS!", F34)), "Tablet/Remote Display: Timer Display", IF(E34="No", "Tablet/Remote Display: Numeric Code", IF(E34="Yes", "User Prompted (Entry Method)", ""))) -> Tablet/Remote Display: Timer Display
A35: Easepal | B35: EI-8602A | C35: Luca V | D35: =COUNTIF('Error Code Log'!$B:$B, C35) -> 0 | E35: N/A | F35: (No Error Codes) | G35: =IF(ISNUMBER(SEARCH("!HAS TIMER DISPLAYS!", F35)), "Tablet/Remote Display: Timer Display", IF(E35="No", "Tablet/Remote Display: Numeric Code", IF(E35="Yes", "User Prompted (Entry Method)", "")))
A36: Easepal | B36: EC-806A | C36: Maestro | D36: =COUNTIF('Error Code Log'!B:B, "Maestro") -> 22 | E36: No | G36: =IF(ISNUMBER(SEARCH("!HAS TIMER DISPLAYS!", F36)), "Tablet/Remote Display: Timer Display", IF(E36="No", "Tablet/Remote Display: Numeric Code", IF(E36="Yes", "User Prompted (Entry Method)", ""))) -> Tablet/Remote Display: Numeric Code
A37: Easepal | B37: EC-806C | C37: Maestro LE | D37: =COUNTIF('Error Code Log'!B:B, "Maestro LE") -> 22 | E37: No | G37: =IF(ISNUMBER(SEARCH("!HAS TIMER DISPLAYS!", F37)), "Tablet/Remote Display: Timer Display", IF(E37="No", "Tablet/Remote Display: Numeric Code", IF(E37="Yes", "User Prompted (Entry Method)", ""))) -> Tablet/Remote Display: Numeric Code
A38: Easepal | B38: EC-806R | C38: Maestro LE 2.0 | D38: =COUNTIF('Error Code Log'!B:B, "Maestro LE 2.0") -> 22 | E38: No | G38: =IF(ISNUMBER(SEARCH("!HAS TIMER DISPLAYS!", F38)), "Tablet/Remote Display: Timer Display", IF(E38="No", "Tablet/Remote Display: Numeric Code", IF(E38="Yes", "User Prompted (Entry Method)", ""))) -> Tablet/Remote Display: Numeric Code
A39: Easepal | B39: EC-8507B | C39: Manhattan Duo | D39: =COUNTIF('Error Code Log'!B:B, "Manhattan Duo") -> 43 | E39: No | G39: =IF(ISNUMBER(SEARCH("!HAS TIMER DISPLAYS!", F39)), "Tablet/Remote Display: Timer Display", IF(E39="No", "Tablet/Remote Display: Numeric Code", IF(E39="Yes", "User Prompted (Entry Method)", ""))) -> Tablet/Remote Display: Numeric Code
A40: Easepal | B40: EI-8701C | C40: Master | D40: =COUNTIF('Error Code Log'!B:B, "Master") -> 29 | E40: No | G40: =IF(ISNUMBER(SEARCH("!HAS TIMER DISPLAYS!", F40)), "Tablet/Remote Display: Timer Display", IF(E40="No", "Tablet/Remote Display: Numeric Code", IF(E40="Yes", "User Prompted (Entry Method)", ""))) -> Tablet/Remote Display: Numeric Code
...

Sheet Error Code Log
A1: Manufacturer | B1: Chair Model | C1: Error Code | D1: Meaning | E1: Troubleshooting Steps | F1: Customer Repairable? | G1: Customer Instructions | H1: Display | I1: Parts Required
A2: iRest | B2: 3D LTX | C2: C1 - C5 | D2: Malfunction: Kneading motor Possible Causes: 1. Damage to the MOS tube of the kneading motor (cannot be controlled). 2. The main PCB is broken, circle number cannot be detected, and the motor is overcurrent. 3. The connecting wire of the manipulator is disconnected, or the plug-in is loose. | E2: Check whether the relevant accessories and wiring harness are in good condition; reorganize and replace them. | F2: No
A3: iRest | B3: 3D LTX | C3: C6 | D3: Malfunction: Damage to MOS tube of air pump (cannot be controlled) Possible Causes: 1. The plug-in is loose. 2. Drive board failure. 3. Open connection harness. | E3: Check whether the relevant circuits, wiring harnesses, and plug-ins are in good condition; reorganize or replace them. | F3: No
A4: iRest | B4: 3D LTX | C4: C7 | D4: Malfunction: Air pump not running, not connected Possible Causes: 1. The plug-in is loose. 2. Drive board failure. 3. Open connection harness. | E4: Check whether the relevant circuits, wiring harnesses, and plug-ins are in good condition; reorganize or replace them. | F4: No
A5: iRest | B5: 3D LTX | C5: C8 | D5: Malfunction: Stroke and overflow of air pump Possible Causes: 1. The plug-in is loose. 2. Drive board failure. 3. Open circuit of connecting wiring harness and overcurrent open circuit. | E5: Check whether the relevant circuits, wiring harnesses, and plug-ins are in good condition; reorganize or replace them. | F5: No
A6: iRest | B6: 3D LTX | C6: C9 | D6: Malfunction: Damage to leg heating MOS tube (cannot be controlled) Possible Causes: 1. The plug-in is loose. 2. Drive board failure. 3. Open circuit of connecting wiring harness and overcurrent open circuit. | E6: Check whether the relevant circuits, wiring harnesses, and plug-ins are in good condition; reorganize or replace them. | F6: No
A7: iRest | B7: 3D LTX | C7: CA / CB | D7: Malfunction: Leg heating is not running, not connected, or thermally protected Possible Causes: 1. The plug-in is loose. 2. Drive board failure. 3. Open circuit of connecting wiring harness and overcurrent open circuit. | E7: Check whether the relevant circuits, wiring harnesses, and plug-ins are in good condition; reorganize or replace them. | F7: No
A8: iRest | B8: 3D LTX | C8: E1 - E3 | D8: Malfunction: Tapping motor Possible Causes: 1. Damage to the MOS tube of the tapping motor (cannot be controlled). 2. The main PCB is broken, circle number cannot be detected, and the motor is overcurrent. 3. The connecting wire of the manipulator is disconnected, or the plug-in is loose. | E8: Check whether the relevant accessories and wiring harness are in good condition; reorganize and replace them. | F8: No
A9: iRest | B9: 3D LTX | C9: E4 - E9 | D9: Malfunction: Calf electric cylinder Possible Causes: 1. Overload or other reasons make the running speed of the calf electric cylinder very slow. 2. The main PCB is broken, plug-in looseness, and motor overcurrent. | E9: Check whether the relevant accessories and wiring harness are in good condition; reorganize and replace them. | F9: No
A10: iRest | B10: 3D LTX | C10: EA - EF | D10: Malfunction: Backrest electric cylinder Possible Causes: 1. Overload or other reasons make the running speed of the backrest electric cylinder very slow. 2. The main PCB is broken, plug-in looseness, and motor overcurrent. | E10: Check whether the relevant accessories and wiring harness are in good condition; reorganize and replace them. | F10: No
A11: iRest | B11: 3D LTX | C11: F1 - F6 | D11: Malfunction: Traveling motor Possible Causes: 1. Damage to the MOS tube of the traveling motor (cannot be controlled). 2. The main PCB is broken, circle number cannot be detected, and the motor is overcurrent. 3. The connecting wire of the manipulator is disconnected, or the plug-in is loose. | E11: Check whether the relevant accessories and wiring harness are in good condition; reorganize and replace them. | F11: No
A12: iRest | B12: 3D LTX | C12: F7 | D12: Malfunction: Power board 24V power supply Possible Causes: 1. The insurance burns out and the power supply is loose. 2. Poor switching power supply. | E12: Check whether the relevant circuits, wiring harnesses, and plug-ins are in good condition; reorganize or replace them. | F12: No
A13: iRest | B13: 3D LTX | C13: F8 | D13: Malfunction: Manipulator 24V power supply Possible Causes: 1. Poor switching power supply. 2. Main PCB failure. 3. The plug-in is loose. | E13: Check whether the relevant circuits, wiring harnesses, and plug-ins are in good condition; reorganize or replace them. | F13: No
A14: iRest | B14: 3D LTX | C14: F9 | D14: Malfunction: Manipulator communication failure Possible Causes: 1. Drive board failure. 2. The plug-in is loose and the connecting harness is open. 3. Detect line faults. | E14: Check whether the relevant circuits, wiring harnesses, and plug-ins are in good condition; reorganize or replace them. | F14: No
A15: iRest | B15: 3D LTX | C15: FA - FC | D15: Malfunction: Back heating Possible Causes: 1. Drive board failure. 2. The plug-in is loose and the connecting harness is open. | E15: Check whether the relevant circuits, wiring harnesses, and plug-ins are in good condition; reorganize or replace them. | F15: Yes | G15: Check connections for the backpad to ensure the heating cord is securely connected
A16: iRest | B16: 3D LTX | C16: FD - FF | D16: Malfunction: Roller motor Possible Causes: 1. Damage to the MOS tube of the roller motor (cannot be controlled). 2. Motor failure. 3. Motor drive circuit problem. 4. Overload or other reasons make the motor unable to work normally. | E16: Check whether the relevant circuits, wiring harnesses, and plug-ins are in good condition; reorganize or replace them. | F16: No
A17: iRest | B17: Acro | C17: A5 | D17: Malfunction: Error detection of foot roller motor drive circuit. Possible Causes: 1. The foot roller motor drive circuit circuit problems. 2. The foot roller motor fails, resulting in excessive current. 3. Overload or other reasons cause the motor to lock up and cause excessive current. | E17: Check whether the relevant circuits, wiring harnesses and plug-ins are in good condition, and reorganize or replace them. | F17: Yes | G17: Check connections for the Footrest to ensure the power cord is securely connected to the base
A18: iRest | B18: Acro | C18: E0 | D18: Malfunction: The upper and lower limit switches of the manipulator detect at the same time. Possible Causes: 1. The upper and lower limit switch lines are not connected well. 2. The upper and lower limit switches are damaged (one or two). | E18: Check whether the relevant accessories and wiring harness are in good condition, and reorganize and replace them. | F18: No
A19: iRest | B19: Acro | C19: E1 | D19: Malfunction: The position signal of up and down walking turns is not detected in unit time. Possible Causes: 1. The upper and lower position signal lines are not connected well. 2. The walking detection code wheel collides with the deflection detection photoelectric pair tube. 3. Move the motor up and down. 4. Moving the motor drive circuit up and down the motherboard. 5. Overload or other reasons make the up-and-down moving motor unable to work normally. | E19: Check whether the relevant accessories and wiring harness are in good condition, and reorganize and replace them. | F19: No
A20: iRest | B20: Acro | C20: E2 | D20: Malfunction: The machine does not detect upper or lower limit signals. Possible Causes: 1. Overload or other reasons make the running speed of the up-and-down moving motor slow. 2. The upper and lower limit switches are damaged. | E20: Check whether the relevant accessories and wiring harness are in good condition, and reorganize and replace them. | F20: No
A21: iRest | B21: Acro | C21: E3 | D21: Malfunction: Kneading width can not be detected. Possible Causes: 1. Kneading width detection photoelectric pipe damage (one or two). 2. Failure of kneading motor. 3. Kneading drive circuit problem. 4. Overload or other reasons make the motor unable to work normally. | E21: Check whether the relevant accessories and wiring harness are in good condition, and reorganize and replace them. | F21: No
A22: iRest | B22: Acro | C22: E4 | D22: Malfunction: The number of turns of the calf lifting motor cannot be detected. Possible Causes: 1. The number of laps detected that Hall was damaged. 2. Motor failure. 3. Motor drive circuit problem. 4. Overload or other reasons make the motor unable to work normally. | E22: Check whether the relevant accessories and wiring harness are in good condition, and reorganize and replace them. | F22: No
A23: iRest | B23: Acro | C23: E5 | D23: Malfunction: The number of turns of backrest lifting motor cannot be detected. Possible Causes: 1. The number of laps detected that Hall was damaged. 2. Motor failure. 3. Motor drive circuit problem. 4. Overload or other reasons make the motor unable to work normally. | E23: Check whether the relevant circuits, wiring harnesses and plug-ins are in good condition, and reorganize or replace them. | F23: No
A24: iRest | B24: Acro | C24: E6E8 | D24: Malfunction: The calf does not rise or fall. Possible Causes: 1. The upper and lower limit switch lines are not connected well. 2. The upper and lower limit switches are damaged (one or two). 3. Heavy or other reasons make the motor run slowly. | E24: Check whether the relevant circuits, wiring harnesses and plug-ins are in good condition, and reorganize or replace them. | F24: No
A25: iRest | B25: Acro | C25: E7 | D25: Malfunction: Upper and lower limit signals are detected at the same time when the backrest is lifted and lowered. Possible Causes: 1. The upper and lower limit switch lines are not connected well. 2. The upper and lower limit switches are damaged (one or two). | E25: Check whether the relevant circuits, wiring harnesses and plug-ins are in good condition, and reorganize or replace them. | F25: No
A26: iRest | B26: Acro | C26: E9 | D26: Malfunction: No upper limit or lower limit signal was detected for backrest lifting. Possible Causes: 1. Heavy or other reasons make the motor run slowly. 2. The upper and lower limit switches are damaged. | E26: Check whether the relevant circuits, wiring harnesses and plug-ins are in good condition, and reorganize or replace them. | F26: No
A27: iRest | B27: Acro | C27: EA | D27: Malfunction: Flap motor drive circuit detection error. Possible Causes: 1. The problem of beating motor drive circuit. 2. Tapping motor failure causes excessive current. 3. Overload or other reasons cause the motor to lock up and cause excessive current. | E27: Check whether the relevant circuits, wiring harnesses and plug-ins are in good condition, and reorganize or replace them. | F27: No
A28: iRest | B28: Acro | C28: EB | D28: Malfunction: Error detection of driving circuit of kneading motor. Possible Causes: 1. Kneading motor drive circuit problem. 2. Kneading motor failure, resulting in excessive current. 3. Overload or other reasons cause the motor to lock up and cause excessive current. | E28: Check whether the relevant circuits, wiring harnesses and plug-ins are in good condition, and reorganize or replace them. | F28: No
A29: iRest | B29: Acro | C29: EC | D29: Malfunction: Error detection of driving circuit of robot walking motor. Possible Causes: 1. Drive circuit of traveling motor. 2. The traveling motor fails, resulting in excessive current. 3. Overload or other reasons cause the motor to lock up and cause excessive current. | E29: Check whether the relevant circuits, wiring harnesses and plug-ins are in good condition, and reorganize or replace them. | F29: No
... A31: iRest | B31: Acro | C31: EE | D31: Malfunction: Error detection of driving circuit of backrest lifting motor. Possible Causes: 1. Drive circuit of backrest lifting motor. 2. The backrest lifting motor fails, resulting in excessive current. 3. Overload or other reasons cause the motor to lock up and cause excessive current. | E31: Check whether the relevant circuits, wiring harnesses and plug-ins are in good condition, and reorganize or replace them. | F31: No
A32: iRest | B32: Allure | C32: B0 | D32: Error in communication between massage hand and PCB | E32: 1. J31 massage hand problem, PCB problem. 2. Massage hand connection problem or plug-in loosened. | F32: Yes | G32: Check the connection of the remote to the base of the chair and ensure it is conected securely
A33: iRest | B33: Allure | C33: B1 | D33: Error communication between massage chair and armrest shortcut key | E33: 1. Armrest shortcut keyboard broken. 2. Link between shortcut key and massage chair loose or wire harness broken. | F33: Yes | G33: Make sure there are no buttons on the side panel that are stuck
A34: iRest | B34: Allure | C34: B2 | D34: Back heating overload or short circuit | E34: 1. Back heating drive circuit has problem. 2. Back heating overload or short circuit. | F34: Yes | G34: Check connections for the backpad to ensure the heating cord is securely connected
A35: iRest | B35: Allure | C35: B3 | D35: Backrest heating temperature sensor has problem | E35: 1. Main board temperature detection circuit has problem. 2. Temperature probe malfunction, wirebroken, or plug-in loop. | F35: Yes | G35: Check connections for the backpad to ensure the heating cord is securely connected
A36: iRest | B36: Allure | C36: B4 | D36: Back heating circuit opening | E36: 1. Main board heating circuit malfunction. 2. Heater circuit opening, plug-in loop or wire broken. | F36: Yes | G36: Check connections for the backpad to ensure the heating cord is securely connected
A37: iRest | B37: Allure | C37: B5 | D37: Error in calf kneadingmotor drive circuitdetection | E37: 1. Calf kneading motor drive circuit has problem. 2. Calf kneading roller motor broken. 3. Overload. | F37: Yes | G37: Check connections for the Footrest to ensure the power cord is securely connected to the base
A38: iRest | B38: Allure | C38: B6 | D38: Calf kneading motor circuit opening | E38: 1. Calf kneading motor drive circuit has problem. 2. Calf kneading motor circuit opening or plug loop. | F38: Yes | G38: Check connections for the Footrest to ensure the power cord is securely connected to the base
A39: iRest | B39: Allure | C39: B7 | D39: Error in foot roller motor drive circuit detection | E39: 1. Foot roller motor drive circuit has problem. 2. Foot roller motor broken. 3. Overload. | F39: Yes | G39: Check connections for the Footrest to ensure the power cord is securely connected to the base
A40: iRest | B40: Allure | C40: B8 | D40: Error detection in 24V AC air pump drive circuit | E40: 1. Air pump drive circuit has problem. 2. Air pump broken. 3. Overload. | F40: No
A41: iRest | B41: Allure | C41: BF | D41: No SD card on bluetooth board | E41: 1. No SD card or not connected well. | F41: No
...

Sheet Error Code Lookup
B2: Error Code Search Tool
B4: Model / Mfg No.:
B5: Error Code(s):
C6: Note: Search multiple error codes using commas (e.g., 44, 46).
C7: Note #2 : If using a serial number, use the first couple numbers and the first letter (e.g., 8602A for 8602A20111028).
B8: Manufacturer | C8: Model | D8: Error Code | E8: Display | F8: Meaning | G8: Troubleshooting | H8: Parts Required | I8: Severity
B9: =IFERROR(__xludf.DUMMYFUNCTION("IF(AND(C4="""", C5=""""), ""Please enter a Model Name or Error Code to search."", IFERROR(FILTER({'Error Code Log'!A2:C1000, 'Error Code Log'!H2:H1000, 'Error Code Log'!D2:E1000, 'Error Code Log'!I2:I1000}, IF(C4="""", ROW('Error Code Log'!B2:B1000)>0, MA"&"P('Error Code Log'!B2:B1000, LAMBDA(model, OR(REGEXMATCH(LOWER(TO_TEXT(model)), LOWER(TRIM(TO_TEXT(C4)))), COUNTIFS('Summary by Mfg & Model'!B:B, ""*""&C4&""*"", 'Summary by Mfg & Model'!C:C, model) > 0)))), IF(C5="""", ROW('Error Code Log'!C2:C1000)>0, R"&"EGEXMATCH(LOWER(TO_TEXT('Error Code Log'!C2:C1000)), ""\b("" & REGEXREPLACE(LOWER(TRIM(TO_TEXT(C5))), ""\s*,\s*"", ""|"") & "")\b""))), IF(C4<>"""", IF(COUNTIFS('Summary by Mfg & Model'!B:B, ""*""&C4&""*"") + COUNTIFS('Summary by Mfg & Model'!C:C, ""*""&C"&"4&""*"") > 0, IF(SUMIFS('Summary by Mfg & Model'!D:D, 'Summary by Mfg & Model'!B:B, ""*""&C4&""*"") + SUMIFS('Summary by Mfg & Model'!D:D, 'Summary by Mfg & Model'!C:C, ""*""&C4&""*"") > 0, ""No matching error codes found for this search."", ""This chair "&"does not have error codes.""), ""There is no information on this chair at this time.""), ""No results found."")))"),"Please enter a Model Name or Error Code to search.") -> Please enter a Model Name or Error Code to search.
